// In this session we are gonna talk about the Finally clause method
// The Try and Catch construct may have one more code clause : finally
// If it Exists it run in all cases;

const n = ()=>{


try{
    let x = 34
    // console.log(action)
    console.log("Function executed sucessfully")
    return
}
catch(error){
    console.log("It is an Error")
    console.log(p)

}
finally{
    console.log("It is a Finally clause example")
    // close the file 
    // Exit the loop 
    // Write tothe log file
}
}

n();
console.log("end")